Workbook
Name Categoria: 'Strutture ricettive'!$A$2:$A$1048576
Name Città: 'Strutture ricettive'!$D$2:$D$1048576
Name Denominazione: 'Strutture ricettive'!$B$2:$B$1048576
Name Indirizzo: 'Strutture ricettive'!$C$2:$C$1048576
Name Indirizzo_di_posta_elettronica: 'Strutture ricettive'!$G$2:$G$1048576
Name Indirizzo_internet: 'Strutture ricettive'!$F$2:$F$1048576
Name Localita: 'Strutture ricettive'!$E$2:$E$1048576
Name Nome_Struttura: '[1]Strutture ricettive'!$B$2:$B$1048576

Sheet Strutture ricettive
A1: Categoria | B1: Denominazione | C1: Indirizzo | D1: Città | E1: Localita | F1: Indirizzo internet | G1: Indirizzo di posta elettronica
A2: TURISMO RURALE | B2: COUNTRY HOUSE LOCALITA' GIROFALCO | C2: Via Girfalco, 26 | D2: URBINO | F2: www.girfalco.it | G2: info@girfalco.it
A3: ALTRI ALLOGGI PRIVATI | B3: STAGNOZZI STEFANIA | C3: Via Candigliano 5 | D3: ACQUALAGNA | E3: ACQUALAGNA | G3: gigliovitto@libero.it
A4: ALTRI ALLOGGI PRIVATI | B4: GORGOLINI ALESSANDRO | C4: Via San Gregorio 9 | D4: ACQUALAGNA | E4: ACQUALAGNA | G4: ale.gorgolini@gmail.com
A5: ALBERGHI | B5: LEON D'ORO | C5: Via Flaminia 213 | D5: ACQUALAGNA | E5: ACQUALAGNA
A6: ALBERGHI | B6: ALBERGO DOMUS MARIAE | C6: viale Ezio Scaglioni 17 | D6: ACQUALAGNA | E6: ACQUALAGNA | G6: giulianaspini@gmail.com
A7: ALTRI ALLOGGI PRIVATI | B7: TORRE COLOMBARA DI FRONTINO | C7: STRADA FRONTINO 24/B | D7: ACQUALAGNA | E7: ACQUALAGNA | G7: luccardi.sandro@gmail.com
A8: BED & BREAKFAST | B8: B&B AQUILEGIA | C8: via Furlo 12 | D8: ACQUALAGNA | E8: Furlo | F8: www.aquilegiabeb.com | G8: info@aquilegiabeb.com
A9: ALLOGGI AGRITURISTICI | B9: DEL FRONTINO | C9: strada frontino 23 | D9: ACQUALAGNA | E9: ACQUALAGNA
A10: ALBERGHI | B10: LA GINESTRA | C10: via Furlo 17 | D10: ACQUALAGNA | E10: ACQUALAGNA | F10: www.ginestrafurlo.it | G10: info@ginestrafurlo.it
A11: ALBERGHI | B11: BIRRA AL POZZO | C11: via Pianacce 12 | D11: ACQUALAGNA | E11: ACQUALAGNA | F11: www.birraalpozzo.it | G11: info@birraalpozzo.it
A12: BED & BREAKFAST | B12: B&B CRISTINI CRISTINA | C12: strada frontino 23 | D12: ACQUALAGNA | E12: ACQUALAGNA | G12: cri.cristini@alice.it
A13: BED & BREAKFAST | B13: B&B MARTELLONI CESARE | C13: via pianacce 67 | D13: ACQUALAGNA | E13: ACQUALAGNA | F13: www.lalocandadellabbazia.it | G13: info@lalocandadellabbazia.it
A14: ALBERGHI | B14: ALBERGO MEUBLE' SHINE | C14: via aldo gamba 54 | D14: ACQUALAGNA | E14: ACQUALAGNA
A15: ALLOGGI AGRITURISTICI | B15: AGRITURISMO CASTELLAGO | C15: strada Castellaro 18 | D15: ACQUALAGNA | E15: ACQUALAGNA | G15: castellago@virgilio.it
A16: ALBERGHI | B16: ALBERGO ANTICO FURLO | C16: via Flaminia 66 | D16: ACQUALAGNA | E16: ACQUALAGNA | F16: www.anticofurlo.it | G16: info@anticofurlo.it
A17: TURISMO RURALE | B17: CA' GARAVANO | C17: strada Frontino 21 | D17: ACQUALAGNA | E17: ACQUALAGNA | F17: www.cagaravano.com | G17: urbini.alessandro@alice.it
A18: ALTRI ALLOGGI PRIVATI | B18: IL CONIO DI DI GIOVANNI FEDERICO | C18: strada pietralatra 1 | D18: ACQUALAGNA | E18: ACQUALAGNA
A19: ALLOGGI AGRITURISTICI | B19: AGRITURISMO I CONTI | C19: via Pieve del Colle 11 b | D19: ACQUALAGNA | E19: pieve del colle | F19: www.agriturismoiconti.it | G19: info@agriturismoiconti.it
A20: ALLOGGI AGRITURISTICI | B20: LA COLOMBARA | C20: strada Frontino 24 | D20: ACQUALAGNA
A21: ALTRI ALLOGGI PRIVATI | B21: STROPPA GIUSEPPE | C21: strada San Gregorio 12 | D21: ACQUALAGNA | E21: Acqualagna | F21: http://lapanoramicadastroppa.webstarts.com/ | G21: stroppag@libero.it
A22: ALTRI ALLOGGI PRIVATI | B22: SERAFINI GIORGIA | D22: ACQUALAGNA
A23: ALTRI ALLOGGI PRIVATI | B23: BETTI VINCENZO | C23: via Pole 69 | D23: ACQUALAGNA
A24: ALLOGGI IN AFFITTO | B24: MARCHEHOLIDAY - CASALE DEGLI ULIVI | C24: strada San Gregorio 1 | D24: ACQUALAGNA | E24: loc.Ca Donnino | F24: www.marcheholiday.it/ulivi | G24: info@marcheholiday.it
A25: AREE DI SOSTA (PLEIN AIR) | B25: AREA SOSTA CAMPER PARCO LE QUERCE | C25: via Pianacce 1 | D25: ACQUALAGNA | E25: RISERVA NATURALE STATALE GOLA DEL FURLO | F25: parcodelfurlo.it | G25: info@parcodelfurlo.it
A26: ALTRI ALLOGGI PRIVATI | B26: BACCHIOCCHI MARIA ELISA | C26: via San Gregorio 17 | D26: ACQUALAGNA | G26: remigio.battistelli@gmail.com
A27: ALTRI ALLOGGI PRIVATI | B27: MARCHETTI LORENZA | C27: via Fossato 37/b | D27: ACQUALAGNA | G27: thomas.clementi@hotmail.it
A28: BED & BREAKFAST | B28: B&B BISCUBIO | C28: via Circonvallazione 46 | D28: APECCHIO | G28: marcellamartinelli17@gmail.com
A29: ALBERGHI | B29: GHIGHETTA | C29: via Borgo Mazzini 40 | D29: APECCHIO | G29: doradimaggio@libero.it
A30: ALLOGGI AGRITURISTICI | B30: AGRITURISMO LA ROCCA | D30: APECCHIO | E30: località la rocca | G30: a.parlani@alice.it
A31: ALLOGGI AGRITURISTICI | B31: AGRITURISMO CA' PIERPAOLI | D31: APECCHIO | E31: località Ca' Pierpaoli | F31: www.chipierpaoli.it | G31: info@chipierpaoli.it
A32: ALLOGGI AGRITURISTICI | B32: AGRITURISMO PIANDIMOLINO | C32: località Pian di Molino 16 | D32: APECCHIO | E32: PIAN DI MOLINO | F32: www.agriturismopiandimolino.it | G32: info@agriturismopiandimolino.it
A33: BED & BREAKFAST | B33: B&B GRANCI MARIA GRAZIA | C33: via Martiri della Liberta' 20 | D33: APECCHIO | E33: APECCHIO
A34: TURISMO RURALE | B34: LE CIOCCHE | D34: APECCHIO | E34: APECCHIO | G34: ale_cipi@live.it
A35: ALLOGGI AGRITURISTICI | B35: FONTE SOMMA | D35: APECCHIO | E35: loc.Fontesomma | F35: www.fontesomma.it | G35: info@fontesomma.it
A36: TURISMO RURALE | B36: COL ALPI | C36: via Circonvallazione 40 | D36: APECCHIO | E36: APECCHIO | G36: ilaesimo@virgilio.it
A37: TURISMO RURALE | B37: COUNTRY HOUSE CACCIABOCCA | C37: vocabolo Caselle 100 | D37: APECCHIO | E37: APECCHIO | F37: www.countryhousechiciabocca.it | G37: info@countryhousechiciabocca.it
A38: BED & BREAKFAST | B38: B&B MOCHI EDMONDO ADOLFO FEDERICO | C38: via dante alighieri 41 | D38: APECCHIO | E38: APECCHIO | G38: elenamochi@hotmail.it
A39: AREE DI SOSTA (PLEIN AIR) | B39: AREA DI SOSTA CAMPER | D39: APECCHIO | E39: APECCHIO
A40: ALLOGGI IN AFFITTO | B40: AFFITTACAMERE APPENNINO | C40: via Garibaldi 9 | D40: APECCHIO | G40: marcellamartinelli17@gmail.com
...

Sheet RICERCA
B1: RICERCA STRUTTURA
B3: NOME STRUTTURA | C3: COUNTRY HOUSE LOCALITA' GIROFALCO | E3: Categoria | H3: Città | J3: Categoria | K3: Denominazione | L3: Indirizzo | M3: Città | N3: Localita | O3: Indirizzo internet | P3: Indirizzo di posta elettronica
B4: CITTA' | C4: =_xlfn.XLOOKUP($C$3,'Strutture ricettive'!B:B,'Strutture ricettive'!D:D,"Non trovata") -> URBINO | E4: BED & BREAKFAST | F4: =COUNTIF('Strutture ricettive'!A:A,E4) -> 1809 | H4: URBINO | J4: TURISMO RURALE | K4: COUNTRY HOUSE LOCALITA' GIROFALCO | L4: Via Girfalco, 26 | M4: URBINO | O4: www.girfalco.it | P4: info@girfalco.it
B5: INDIRIZZO | C5: =_xlfn.XLOOKUP($C$3,'Strutture ricettive'!B:B,'Strutture ricettive'!C:C,"Non trovata") -> Via Girfalco, 26 | E5: STABILIMENTI BALNEARI | F5: =COUNTIF('Strutture ricettive'!A:A,E5) -> 850 | J5: ALTRI ALLOGGI PRIVATI | K5: PESCHKE MARTIN MICHAEL ERNST | L5: strada provinciale Peglio San Donato 17 | M5: URBINO | O5: www.capiero.it | P5: email.capiero@googlemail.com
B6: EMAIL | C6: =_xlfn.XLOOKUP($C$3,'Strutture ricettive'!B:B,'Strutture ricettive'!G:G,"Non trovata") -> info@girfalco.it | E6: ALLOGGI AGRITURISTICI | F6: =COUNTIF('Strutture ricettive'!A:A,E6) -> 830 | J6: BED & BREAKFAST | K6: B&B IL MONCHETTO | L6: via Monte Pallotta 31 | M6: URBINO | N6: Cà Staccolo | P6: lauraquaresima@virgilio.it
B7: INDIRIZZO WEB | C7: =_xlfn.XLOOKUP($C$3,'Strutture ricettive'!B:B,'Strutture ricettive'!F:F,"Non trovata") -> www.girfalco.it | E7: ALBERGHI | F7: =COUNTIF('Strutture ricettive'!A:A,E7) -> 814 | J7: ALTRI ALLOGGI PRIVATI | K7: VILLA LAURA | L7: via E. Mattei 30 | M7: URBINO | O7: www.vacanzeavillalaura.it | P7: vacanzevillalaura@gmail.com
B8: Numero totale strutture | C8: =COUNTA('Strutture ricettive'!B:B)-1 -> 6258 | E8: ALTRI ALLOGGI PRIVATI | F8: =COUNTIF('Strutture ricettive'!A:A,E8) -> 721 | J8: BED & BREAKFAST | K8: B&B IL CASALE DEL DUCA | L8: strada provinciale Montefabbri 104 | M8: URBINO | N8: Cal Duca | O8: www.ilcasaledelduca.it | P8: info@ilcasaledelduca.it
B9: Numero strutture per LOCALITA' | C9: =COUNTIF('Strutture ricettive'!D:D,C4) -> 144 | E9: ALLOGGI IN AFFITTO | F9: =COUNTIF('Strutture ricettive'!A:A,E9) -> 541 | J9: BED & BREAKFAST | K9: DOMENICA B&B | L9: via Don Luigi Sturzo 11 | M9: URBINO | N9: loc. Canavaccio | P9: patrizia.diotallevi62@hotmail.com
E10: TURISMO RURALE | F10: =COUNTIF('Strutture ricettive'!A:A,E10) -> 304 | J10: BED & BREAKFAST | K10: B&B CA' FABBRO | L10: strada provinciale Pieve di Cagna 33/35 | M10: URBINO | P10: mprossi1@virgilio.it
B11: Esercizio 10 | E11: CAMPEGGI | F11: =COUNTIF('Strutture ricettive'!A:A,E11) -> 93 | J11: BED & BREAKFAST | K11: B&B SASSO FIORITO | L11: via Monte Pallotta 12 | M11: URBINO | N11: loc. Sasso | P11: mauro.sisti@alice.it
B12: Probabilita dai conteggi | E12: AREE DI SOSTA (PLEIN AIR) | F12: =COUNTIF('Strutture ricettive'!A:A,E12) -> 86 | J12: ALLOGGI AGRITURISTICI | K12: CA' LUPINO | L12: via Cà Bergamo 44 | M12: URBINO | O12: www.calupino.it | P12: info@calupino.it
B13: P(Albergo) | C13: =F7/C8 -> 0.13007351 | E13: CASE PER FERIE | F13: =COUNTIF('Strutture ricettive'!A:A,E13) -> 82 | J13: BED & BREAKFAST | K13: B&B A CASA MIA | L13: via Colonna 25 | M13: URBINO | N13: loc. Trasanni | P13: tecla1111@yahoo.it
B14: P(Bed & Breakfast) | C14: =F4/C8 -> 0.28906999 | E14: RESIDENZE TURISTICO ALBERGHIERE | F14: =COUNTIF('Strutture ricettive'!A:A,E14) -> 52 | J14: BED & BREAKFAST | K14: B&B AMPIAVISTA | L14: via Bramante 66/a | M14: URBINO | P14: ampiavista@libero.it
B15: P(2 Alberghi su 2 Estrazioni) | C15: =(F7/C8)^2 -> 0.016919117 | E15: OSTELLI PER LA GIOVENTU' | F15: =COUNTIF('Strutture ricettive'!A:A,E15) -> 30 | J15: BED & BREAKFAST | K15: B&B CASA NELLA | L15: via dei Vasari 13 | M15: URBINO | P15: susix1it@yahoo.it
E16: VILLAGGI TURISTICI | F16: =COUNTIF('Strutture ricettive'!A:A,E16) -> 17 | J16: ALTRI ALLOGGI PRIVATI | K16: CA' AURORA | L16: via Nazionale Boccatrabaria ovest 144 | M16: URBINO
E17: RIFUGI | F17: =COUNTIF('Strutture ricettive'!A:A,E17) -> 16 | J17: ALBERGHI | K17: HOTEL MAMIANI | L17: via Errigo Bernini 6 | M17: URBINO | N17: URBINO | O17: www.hotelmamiani.it | P17: info@hotelmamiani.it
E18: ALTRI ESERCIZI RICETTIVI | F18: =COUNTIF('Strutture ricettive'!A:A,E18) -> 13 | J18: BED & BREAKFAST | K18: B&B CA' IMELDE | L18: via Bocca Trabaria 123 | M18: URBINO | P18: arcalavalle@gmail.com
J19: BED & BREAKFAST | K19: B&B VILLA CINI | L19: via S.P.Montefabbri 17 | M19: URBINO | O19: www.bbvillacini.com | P19: info@bbvillacini.com
J20: ALTRI ALLOGGI PRIVATI | K20: ACERO FRANCESCO E FILIPPO | L20: via Monte Polo 10 | M20: URBINO | P20: m.g.acero@alice.it
J21: ALTRI ALLOGGI PRIVATI | K21: ACERO MARIA GRAZIA | L21: via Monte Polo 8 | M21: URBINO | P21: m.g.acero@alice.it
J22: BED & BREAKFAST | K22: B&B LA NATURA | L22: via San Bartolo - loc. Rancitella 2 | M22: URBINO | N22: loc. Rancitella - via San Bartolo | O22: www.bblanatura.it | P22: info@bblanatura.it
J23: BED & BREAKFAST | K23: B&B LA CASETTA DEL BORGO | L23: via del Borgo Antico 5 | M23: URBINO | N23: loc.Pantiere | P23: beblacasettadelborgo@gmail.com
J24: BED & BREAKFAST | K24: B&B MARIA GIUSEPPINA MASTORE | L24: via San Marino 19 | M24: URBINO | P24: pinamastore@gmail.com
J25: BED & BREAKFAST | K25: B&B ALBORNOZ | L25: via dei Maceri 23 | M25: URBINO | O25: www.bbalbornoz.com | P25: email@bbalbornoz.com
J26: ALLOGGI AGRITURISTICI | K26: CA' FERRO | L26: Bocca Trabaria Ovest 126 | M26: URBINO | N26: Tufo | O26: agriturismocaferro.it | P26: fogliaa84@libero.it
J27: BED & BREAKFAST | K27: B&B SANPOLO 1544 | L27: via Aurelio Saffi 3 | M27: URBINO | O27: www.sanpolo1544.it | P27: info@sanpolo1544.it
J28: BED & BREAKFAST | K28: B&B IL GHETTO | L28: via Stretta 31 | M28: URBINO | N28: URBINO | O28: www.ilghetto.net | P28: ilghettourbino@gmail.com
J29: ALTRI ESERCIZI RICETTIVI | K29: ISTITUTO SANTA FELICITA | L29: via del fiancale 1 | M29: URBINO | N29: URBINO
J30: ALTRI ESERCIZI RICETTIVI | K30: PENSIONATO MARIA IMMACOLATA | L30: via giuseppe mazzini 36 | M30: URBINO | N30: URBINO | P30: mpvurbino@tiscali.it
J31: BED & BREAKFAST | K31: ANNA BED & BREAKFAST | L31: via nazionale 1 | M31: URBINO | N31: URBINO | O31: www.anna-bed-breakfast.it | P31: ardu09@gmail.com
J32: BED & BREAKFAST | K32: B&B VILLA GERHARDT | L32: localita' rancitella via san bartolo 23 | M32: URBINO | N32: URBINO
J33: TURISMO RURALE | K33: COUNTRY HOUSE AI CIPRESSI | L33: via mainardi 3 | M33: URBINO | N33: URBINO | O33: http://www.cipressiurbino.it | P33: cipressiurbino@gmail.com
J34: BED & BREAKFAST | K34: B&B DELLE DUCHESSE | L34: via Santa Margherita 22 | M34: URBINO | N34: URBINO | O34: www.albergoraffaello.com | P34: info@albergoraffaello.com
J35: BED & BREAKFAST | K35: B&B LA VALLE | L35: Via della valle 1 | M35: URBINO | N35: URBINO | O35: www.bblavalle.com | P35: prenotazioni@bblavalle.com
J36: BED & BREAKFAST | K36: B&B ACACIA | L36: via strada provinciale numero 9 feltresca 63 | M36: URBINO | N36: URBINO | O36: www.acaciaurbino.it | P36: sdenti@libero.it
J37: BED & BREAKFAST | K37: B&B ABACO - ALMA DOMUS | L37: via mainardi 1 | M37: URBINO | N37: URBINO | O37: www.almadomus.it | P37: almadomus@gmail.com
J38: ALLOGGI AGRITURISTICI | K38: IL CASALE NEL TUFO | L38: localita' Rancitella 1 | M38: URBINO | N38: URBINO | P38: faustofoglietta@interfree.it
J39: ALLOGGI AGRITURISTICI | K39: AGRITURISMO CA' MATTIOLI | L39: via Checiccarino 17 | M39: URBINO | N39: loc. Montecalende | P39: m.romagnoli@cia.it
J40: BED & BREAKFAST | K40: B&B URBINO | L40: via Fornace 1 | M40: URBINO | N40: URBINO | P40: marosx@vodafone.it
J41: BED & BREAKFAST | K41: B&B SAN FRANCESCO | L41: via raffaello 9 | M41: URBINO | N41: URBINO | O41: www.bbsanfrancescourbino.com | P41: info@bbsanfrancescourbino.com
...
